{
 "cells": [
  {
   "cell_type": "markdown",
   "metadata": {},
   "source": [
    "Imports"
   ]
  },
  {
   "cell_type": "code",
   "execution_count": null,
   "metadata": {},
   "outputs": [],
   "source": [
    "from drawing_bot_api.trajectory_optimizer.shape_generator import ShapeGenerator\n",
    "from drawing_bot_api.trajectory_optimizer.shape_generator import RESTING_POINT\n",
    "from drawing_bot_api import DrawingBot\n",
    "from drawing_bot_api.trajectory_optimizer.image_processor import ImageProcessor\n",
    "from drawing_bot_api.trajectory_optimizer.wiper import Wiper\n",
    "from drawing_bot_api.trajectory_optimizer.simulator import PatternErrorSim"
   ]
  },
  {
   "cell_type": "markdown",
   "metadata": {},
   "source": [
    "Inits"
   ]
  },
  {
   "cell_type": "code",
   "execution_count": null,
   "metadata": {},
   "outputs": [
    {
     "name": "stdout",
     "output_type": "stream",
     "text": [
      "Unit set to \"mm\".\n"
     ]
    },
    {
     "name": "stderr",
     "output_type": "stream",
     "text": [
      "2024-12-03 21:09:09.499143: I tensorflow/core/platform/cpu_feature_guard.cc:151] This TensorFlow binary is optimized with oneAPI Deep Neural Network Library (oneDNN) to use the following CPU instructions in performance-critical operations:  AVX2 FMA\n",
      "To enable them in other operations, rebuild TensorFlow with the appropriate compiler flags.\n"
     ]
    }
   ],
   "source": [
    "shape_generator = ShapeGenerator()\n",
    "drawing_bot = DrawingBot()\n",
    "image_processor = ImageProcessor()\n",
    "wiper = Wiper()\n",
    "error_simulator = PatternErrorSim(strength=15, pattern_length=20)"
   ]
  },
  {
   "cell_type": "markdown",
   "metadata": {},
   "source": [
    "Generate a random shape and extract its points"
   ]
  },
  {
   "cell_type": "code",
   "execution_count": 3,
   "metadata": {},
   "outputs": [],
   "source": [
    "for shape in shape_generator():\n",
    "    drawing_bot.add_shape(shape)\n",
    "\n",
    "points = drawing_bot._get_all_points()"
   ]
  },
  {
   "cell_type": "markdown",
   "metadata": {},
   "source": [
    "Adjust the trajectory via model"
   ]
  },
  {
   "cell_type": "code",
   "execution_count": null,
   "metadata": {},
   "outputs": [
    {
     "name": "stdout",
     "output_type": "stream",
     "text": [
      "(10,)\n",
      "(9,)\n"
     ]
    },
    {
     "ename": "ValueError",
     "evalue": "in user code:\n\n    File \"/Library/Frameworks/Python.framework/Versions/3.8/lib/python3.8/site-packages/keras/engine/training.py\", line 1801, in predict_function  *\n        return step_function(self, iterator)\n    File \"/Library/Frameworks/Python.framework/Versions/3.8/lib/python3.8/site-packages/keras/engine/training.py\", line 1790, in step_function  **\n        outputs = model.distribute_strategy.run(run_step, args=(data,))\n    File \"/Library/Frameworks/Python.framework/Versions/3.8/lib/python3.8/site-packages/keras/engine/training.py\", line 1783, in run_step  **\n        outputs = model.predict_step(data)\n    File \"/Library/Frameworks/Python.framework/Versions/3.8/lib/python3.8/site-packages/keras/engine/training.py\", line 1751, in predict_step\n        return self(x, training=False)\n    File \"/Library/Frameworks/Python.framework/Versions/3.8/lib/python3.8/site-packages/keras/utils/traceback_utils.py\", line 67, in error_handler\n        raise e.with_traceback(filtered_tb) from None\n    File \"/Library/Frameworks/Python.framework/Versions/3.8/lib/python3.8/site-packages/keras/engine/input_spec.py\", line 264, in assert_input_compatibility\n        raise ValueError(f'Input {input_index} of layer \"{layer_name}\" is '\n\n    ValueError: Input 0 of layer \"sequential\" is incompatible with the layer: expected shape=(None, 10), found shape=(None, 9)\n",
     "output_type": "error",
     "traceback": [
      "\u001b[0;31m---------------------------------------------------------------------------\u001b[0m",
      "\u001b[0;31mValueError\u001b[0m                                Traceback (most recent call last)",
      "Cell \u001b[0;32mIn[4], line 1\u001b[0m\n\u001b[0;32m----> 1\u001b[0m new_points \u001b[38;5;241m=\u001b[39m \u001b[43mmodel\u001b[49m\u001b[38;5;241;43m.\u001b[39;49m\u001b[43madjust_trajectory\u001b[49m\u001b[43m(\u001b[49m\u001b[43mpoints\u001b[49m\u001b[43m)\u001b[49m\n\u001b[1;32m      2\u001b[0m \u001b[38;5;28mprint\u001b[39m(new_points)\n",
      "File \u001b[0;32m~/Documents/Dateien/Privat/Projekte/Bachelorarbeit/Project/MIRMI_2DOF_Drawing_Bot/code/api/drawing_bot_api/trajectory_optimizer/training.py:57\u001b[0m, in \u001b[0;36mTrainer.adjust_trajectory\u001b[0;34m(self, trajectory)\u001b[0m\n\u001b[1;32m     55\u001b[0m     _input \u001b[38;5;241m=\u001b[39m _input\u001b[38;5;241m.\u001b[39mreshape(\u001b[38;5;241m1\u001b[39m, \u001b[38;5;241m-\u001b[39m\u001b[38;5;241m1\u001b[39m)\n\u001b[1;32m     56\u001b[0m     \u001b[38;5;66;03m#print(_input.shape)\u001b[39;00m\n\u001b[0;32m---> 57\u001b[0m     _new_point \u001b[38;5;241m=\u001b[39m \u001b[38;5;28;43mself\u001b[39;49m\u001b[38;5;241;43m.\u001b[39;49m\u001b[43mmodel\u001b[49m\u001b[38;5;241;43m.\u001b[39;49m\u001b[43mpredict\u001b[49m\u001b[43m(\u001b[49m\u001b[43m_input\u001b[49m\u001b[43m)\u001b[49m\n\u001b[1;32m     58\u001b[0m     trajectory[_index] \u001b[38;5;241m=\u001b[39m _new_point\n\u001b[1;32m     60\u001b[0m \u001b[38;5;28;01mreturn\u001b[39;00m trajectory\n",
      "File \u001b[0;32m/Library/Frameworks/Python.framework/Versions/3.8/lib/python3.8/site-packages/keras/utils/traceback_utils.py:67\u001b[0m, in \u001b[0;36mfilter_traceback.<locals>.error_handler\u001b[0;34m(*args, **kwargs)\u001b[0m\n\u001b[1;32m     65\u001b[0m \u001b[38;5;28;01mexcept\u001b[39;00m \u001b[38;5;167;01mException\u001b[39;00m \u001b[38;5;28;01mas\u001b[39;00m e:  \u001b[38;5;66;03m# pylint: disable=broad-except\u001b[39;00m\n\u001b[1;32m     66\u001b[0m   filtered_tb \u001b[38;5;241m=\u001b[39m _process_traceback_frames(e\u001b[38;5;241m.\u001b[39m__traceback__)\n\u001b[0;32m---> 67\u001b[0m   \u001b[38;5;28;01mraise\u001b[39;00m e\u001b[38;5;241m.\u001b[39mwith_traceback(filtered_tb) \u001b[38;5;28;01mfrom\u001b[39;00m \u001b[38;5;28;01mNone\u001b[39;00m\n\u001b[1;32m     68\u001b[0m \u001b[38;5;28;01mfinally\u001b[39;00m:\n\u001b[1;32m     69\u001b[0m   \u001b[38;5;28;01mdel\u001b[39;00m filtered_tb\n",
      "File \u001b[0;32m/Library/Frameworks/Python.framework/Versions/3.8/lib/python3.8/site-packages/tensorflow/python/framework/func_graph.py:1147\u001b[0m, in \u001b[0;36mfunc_graph_from_py_func.<locals>.autograph_handler\u001b[0;34m(*args, **kwargs)\u001b[0m\n\u001b[1;32m   1145\u001b[0m \u001b[38;5;28;01mexcept\u001b[39;00m \u001b[38;5;167;01mException\u001b[39;00m \u001b[38;5;28;01mas\u001b[39;00m e:  \u001b[38;5;66;03m# pylint:disable=broad-except\u001b[39;00m\n\u001b[1;32m   1146\u001b[0m   \u001b[38;5;28;01mif\u001b[39;00m \u001b[38;5;28mhasattr\u001b[39m(e, \u001b[38;5;124m\"\u001b[39m\u001b[38;5;124mag_error_metadata\u001b[39m\u001b[38;5;124m\"\u001b[39m):\n\u001b[0;32m-> 1147\u001b[0m     \u001b[38;5;28;01mraise\u001b[39;00m e\u001b[38;5;241m.\u001b[39mag_error_metadata\u001b[38;5;241m.\u001b[39mto_exception(e)\n\u001b[1;32m   1148\u001b[0m   \u001b[38;5;28;01melse\u001b[39;00m:\n\u001b[1;32m   1149\u001b[0m     \u001b[38;5;28;01mraise\u001b[39;00m\n",
      "\u001b[0;31mValueError\u001b[0m: in user code:\n\n    File \"/Library/Frameworks/Python.framework/Versions/3.8/lib/python3.8/site-packages/keras/engine/training.py\", line 1801, in predict_function  *\n        return step_function(self, iterator)\n    File \"/Library/Frameworks/Python.framework/Versions/3.8/lib/python3.8/site-packages/keras/engine/training.py\", line 1790, in step_function  **\n        outputs = model.distribute_strategy.run(run_step, args=(data,))\n    File \"/Library/Frameworks/Python.framework/Versions/3.8/lib/python3.8/site-packages/keras/engine/training.py\", line 1783, in run_step  **\n        outputs = model.predict_step(data)\n    File \"/Library/Frameworks/Python.framework/Versions/3.8/lib/python3.8/site-packages/keras/engine/training.py\", line 1751, in predict_step\n        return self(x, training=False)\n    File \"/Library/Frameworks/Python.framework/Versions/3.8/lib/python3.8/site-packages/keras/utils/traceback_utils.py\", line 67, in error_handler\n        raise e.with_traceback(filtered_tb) from None\n    File \"/Library/Frameworks/Python.framework/Versions/3.8/lib/python3.8/site-packages/keras/engine/input_spec.py\", line 264, in assert_input_compatibility\n        raise ValueError(f'Input {input_index} of layer \"{layer_name}\" is '\n\n    ValueError: Input 0 of layer \"sequential\" is incompatible with the layer: expected shape=(None, 10), found shape=(None, 9)\n"
     ]
    }
   ],
   "source": [
    "from drawing_bot_api.trajectory_optimizer.training import Trainer\n",
    "model = Trainer()\n",
    "\n",
    "new_points = model.adjust_trajectory(points)\n",
    "print(new_points)"
   ]
  }
 ],
 "metadata": {
  "kernelspec": {
   "display_name": "Python 3",
   "language": "python",
   "name": "python3"
  },
  "language_info": {
   "codemirror_mode": {
    "name": "ipython",
    "version": 3
   },
   "file_extension": ".py",
   "mimetype": "text/x-python",
   "name": "python",
   "nbconvert_exporter": "python",
   "pygments_lexer": "ipython3",
   "version": "3.8.5"
  }
 },
 "nbformat": 4,
 "nbformat_minor": 2
}
